/**
 * Integration test for AuthErrorToast with simplified error handling
 * Tests the implementation of task 6: Add proper error handling without complex retry logic
 */

import React from 'react';
import { render, screen } from '@testing-library/react';
import AuthErrorToast from '../AuthErrorToast';
import { AuthProvider } from '@/contexts/AuthContext';
import { SupabaseProvider } from '@/contexts/SupabaseProvider';

// Mock Supabase client
const mockSupabaseClient = {
  auth: {
    onAuthStateChange: jest.fn(() => ({
      data: { subscription: { unsubscribe: jest.fn() } }
    }))
  }
};

// Mock SupabaseProvider
jest.mock('@/contexts/SupabaseProvider', () => ({
  SupabaseProvider: ({ children }: { children: React.ReactNode }) => children,
  useSupabaseClient: () => mockSupabaseClient,
  useSupabaseStatus: () => ({ isReady: true, error: null })
}));

// Mock AuthContext with error state
const mockAuthContextWithError = {
  user: null,
  userProfile: null,
  authStatus: 'unauthenticated' as const,
  error: {
    type: 'network' as const,
    message: '네트워크 연결을 확인해주세요',
    code: 'NETWORK_ERROR'
  },
  lastUpdated: new Date()
};

const mockAuthContextWithoutError = {
  user: null,
  userProfile: null,
  authStatus: 'unauthenticated' as const,
  error: null,
  lastUpdated: new Date()
};

jest.mock('@/contexts/AuthContext', () => ({
  AuthProvider: ({ children }: { children: React.ReactNode }) => children,
  useAuthContext: jest.fn()
}));

const { useAuthContext } = require('@/contexts/AuthContext');

describe('AuthErrorToast Integration', () => {
  beforeEach(() => {
    jest.clearAllMocks();
    // Mock console methods
    jest.spyOn(console, 'error').mockImplementation(() => {});
    jest.spyOn(console, 'log').mockImplementation(() => {});
  });

  afterEach(() => {
    jest.restoreAllMocks();
  });

  it('should display error through existing UI patterns', () => {
    useAuthContext.mockReturnValue(mockAuthContextWithError);

    render(<AuthErrorToast />);

    // Should log error for debugging
    expect(console.error).toHaveBeenCalledWith(
      '[AuthErrorToast] Displaying error:',
      expect.objectContaining({
        type: 'network',
        code: 'NETWORK_ERROR',
        message: '네트워크 연결을 확인해주세요',
        timestamp: expect.any(String)
      })
    );
  });

  it('should not display anything when there is no error', () => {
    useAuthContext.mockReturnValue(mockAuthContextWithoutError);

    render(<AuthErrorToast />);

    // Should not log any error
    expect(console.error).not.toHaveBeenCalledWith(
      '[AuthErrorToast] Displaying error:',
      expect.anything()
    );
  });

  it('should handle different error types correctly', () => {
    const testCases = [
      {
        error: {
          type: 'network' as const,
          message: '네트워크 연결을 확인해주세요',
          code: 'NETWORK_ERROR'
        },
        expectedTitle: '연결 오류'
      },
      {
        error: {
          type: 'auth' as const,
          message: '인증에 문제가 발생했습니다',
          code: 'AUTH_ERROR'
        },
        expectedTitle: '인증 오류'
      },
      {
        error: {
          type: 'unknown' as const,
          message: '알 수 없는 오류가 발생했습니다',
          code: 'UNKNOWN_ERROR'
        },
        expectedTitle: '시스템 오류'
      }
    ];

    testCases.forEach((testCase) => {
      useAuthContext.mockReturnValue({
        ...mockAuthContextWithoutError,
        error: testCase.error
      });

      render(<AuthErrorToast />);

      // Should log error with correct categorization
      expect(console.error).toHaveBeenCalledWith(
        '[AuthErrorToast] Displaying error:',
        expect.objectContaining({
          type: testCase.error.type,
          code: testCase.error.code,
          message: testCase.error.message,
          timestamp: expect.any(String)
        })
      );

      // Clear mocks for next iteration
      jest.clearAllMocks();
      jest.spyOn(console, 'error').mockImplementation(() => {});
    });
  });

  it('should not implement complex recovery strategies', () => {
    useAuthContext.mockReturnValue(mockAuthContextWithError);

    render(<AuthErrorToast />);

    // Should not attempt any automatic recovery
    // The component should only display the error, not try to fix it
    expect(console.error).toHaveBeenCalledWith(
      '[AuthErrorToast] Displaying error:',
      expect.any(Object)
    );

    // Should also call toast.error which logs to console.error
    expect(console.error).toHaveBeenCalledWith(
      '❌ 연결 오류: 네트워크 연결을 확인해주세요',
      '오류 코드: NETWORK_ERROR'
    );

    // Should not call any retry or recovery functions
    // (This is verified by the absence of additional console logs or function calls)
  });
});